<?xml version="1.0" ?>
<!-- =================================================================================== -->
<!-- |    This document was autogenerated by xacro from my_robot_urdf.xacro            | -->
<!-- |    EDITING THIS FILE BY HAND IS NOT RECOMMENDED                                 | -->
<!-- =================================================================================== -->
<robot name="box_bot">
  <!-- Добавления материалов и скриптов -->
  <!-- This file is not a robot in and of itself, it just contains some useful tags that could be included in any robot -->
  <!-- This file is not a robot in and of itself, it just contains some useful tags that could be included in any robot -->
  <!-- Specify some colours -->
  <material name="primary">
    <color rgba="1 0.3 0.1 1"/>
  </material>
  <material name="secondary">
    <color rgba="0.7 0.15 0.01 1"/>
  </material>
  <material name="base">
    <color rgba="0.1 0.1 0.1 1"/>
  </material>
  <!-- Добавления материалов и скриптов -->
  <!-- This file is not a robot in and of itself, it just contains some useful tags that could be included in any robot -->
  <link name="base_link"/>
  <link name="chassi">
    <inertial>
      <origin xyz="0.0 0.0 0.15"/>
      <mass value="0.1"/>
      <inertia ixx="0.0015" ixy="0.0" ixz="0.0" iyy="0.0020833333333333333" iyz="0.0" izz="0.0020833333333333333"/>
    </inertial>
    <visual name="">
      <origin rpy="0.0 0.0 0.0" xyz="0.0 0.0 0.15"/>
      <geometry>
        <box size="0.4 0.3 0.3"/>
      </geometry>
      <material name="">
        <color rgba="1.0 0.0 0.0 1.0"/>
        <texture filename=""/>
      </material>
    </visual>
    <collision>
      <origin rpy="0.0 0.0 0.0" xyz="0.0 0.0 0.15"/>
      <geometry>
        <box size="0.4 0.3 0.3"/>
      </geometry>
    </collision>
  </link>
  <joint name="fixed_join" type="fixed">
    <origin rpy="0.0 0.0 0.0" xyz="0.0 0.0 0.0"/>
    <parent link="base_link"/>
    <child link="chassi"/>
  </joint>
  <link name="wheel_left">
    <inertial>
      <origin xyz="0.0 0.015 0.0"/>
      <mass value="0.1"/>
      <inertia ixx="0.00013000000000000002" ixy="0.0" ixz="0.0" iyy="0.00013000000000000002" iyz="0.0" izz="0.00024500000000000005"/>
    </inertial>
    <visual name="">
      <origin rpy="1.5707963267948966 0.0 0.0" xyz="0.0 0.015 0.0"/>
      <geometry>
        <cylinder length="0.03" radius="0.07"/>
      </geometry>
      <material name="">
        <color rgba="1.0 0.0 0.0 1.0"/>
        <texture filename=""/>
      </material>
    </visual>
    <collision>
      <origin rpy="1.5707963267948966 0.0 0.0" xyz="0.0 0.015 0.0"/>
      <geometry>
        <cylinder length="0.03" radius="0.07"/>
      </geometry>
    </collision>
  </link>
  <joint name="join_wheel_left" type="continuous">
    <origin xyz="0.0 0.15 0.0"/>
    <parent link="chassi"/>
    <child link="wheel_left"/>
    <axis xyz="0.0 -1 0.0"/>
  </joint>
  <link name="wheel_right">
    <inertial>
      <origin xyz="0.0 0.015 0.0"/>
      <mass value="0.1"/>
      <inertia ixx="0.00013000000000000002" ixy="0.0" ixz="0.0" iyy="0.00013000000000000002" iyz="0.0" izz="0.00024500000000000005"/>
    </inertial>
    <visual name="">
      <origin rpy="1.5707963267948966 0.0 0.0" xyz="0.0 0.015 0.0"/>
      <geometry>
        <cylinder length="0.03" radius="0.07"/>
      </geometry>
      <material name="">
        <color rgba="1.0 0.0 0.0 1.0"/>
        <texture filename=""/>
      </material>
    </visual>
    <collision>
      <origin rpy="1.5707963267948966 0.0 0.0" xyz="0.0 0.015 0.0"/>
      <geometry>
        <cylinder length="0.03" radius="0.07"/>
      </geometry>
    </collision>
  </link>
  <joint name="join_wheel_right" type="continuous">
    <origin xyz="0.0 -0.18 0.0"/>
    <parent link="chassi"/>
    <child link="wheel_right"/>
    <axis xyz="0.0 -1 0.0"/>
  </joint>
  <!-- DEPTH CAMERA -->
  <link name="base_depth_camera">
    <inertial>
      <origin xyz="0.0 0.0 0.015"/>
      <mass value="0.1"/>
      <inertia ixx="0.0015" ixy="0.0" ixz="0.0" iyy="0.0020833333333333333" iyz="0.0" izz="0.0020833333333333333"/>
    </inertial>
    <visual name="">
      <origin rpy="0.0 0.0 0.0" xyz="0.0 0.0 0.015"/>
      <geometry>
        <box size="0.01 0.01 0.03"/>
      </geometry>
      <material name="">
        <color rgba="1.0 0.0 0.0 1.0"/>
        <texture filename=""/>
      </material>
    </visual>
    <collision>
      <origin rpy="0.0 0.0 0.0" xyz="0.0 0.0 0.015"/>
      <geometry>
        <box size="0.01 0.01 0.03"/>
      </geometry>
    </collision>
  </link>
  <joint name="base_depth_camera_joint" type="fixed">
    <origin rpy="0.0 0.0 0.0" xyz=" 0.18000000000000002 0.0 0.3"/>
    <parent link="chassi"/>
    <child link="base_depth_camera"/>
  </joint>
  <link name="depth_camera">
    <inertial>
      <origin rpy="0.0 0.0 0.0" xyz="0.0 0.0 0.02"/>
      <mass value="0.1"/>
      <inertia ixx="0.0015" ixy="0.0" ixz="0.0" iyy="0.0020833333333333333" iyz="0.0" izz="0.0020833333333333333"/>
    </inertial>
    <visual name="">
      <origin rpy="0.0 0.0 0.0" xyz="0.0 0.0 0.02"/>
      <geometry>
        <box size="0.06 0.24 0.04"/>
      </geometry>
      <material name="">
        <color rgba="1.0 0.0 0.0 1.0"/>
        <texture filename=""/>
      </material>
    </visual>
    <collision>
      <origin rpy="0.0 0.0 0.0" xyz="0.0 0.0 0.02"/>
      <geometry>
        <box size="0.06 0.24 0.04"/>
      </geometry>
    </collision>
  </link>
  <joint name="depth_camera_joint" type="fixed">
    <origin rpy="0.0 0.0 0.0" xyz="0.0 0.0 0.03"/>
    <parent link="base_depth_camera"/>
    <child link="depth_camera"/>
  </joint>
  <gazebo>
    <plugin filename="gz-sim-diff-drive-system" name="gz::sim::systems::DiffDrive">
      <!-- Wheel information -->
      <left_joint>join_wheel_left</left_joint>
      <right_joint>join_wheel_right</right_joint>
      <wheel_separation>0.3</wheel_separation>
      <wheel_radius>0.07</wheel_radius>
      <!-- Limits -->
      <max_linear_acceleration>10</max_linear_acceleration>
      <!-- Output -->
      <odom_topic>odom</odom_topic>
      <!-- OLD from <odometry_topic> -->
      <frame_id>odom</frame_id>
      <!-- OLD from <odometry_frame> -->
      <child_frame_id>base_link</child_frame_id>
      <!-- OLD from <robot_base_frame> -->
      <odom_publisher_frequency>30</odom_publisher_frequency>
      <!-- OLD from <update_rate>-->
      <!-- Short topic name for tf output -->
      <tf_topic>/tf</tf_topic>
      <topic>cmd_vel</topic>
    </plugin>
    <plugin filename="gz-sim-joint-state-publisher-system" name="gz::sim::systems::JointStatePublisher">
      <topic>joint_states</topic>
      <!--from <ros><remapping> -->
      <joint_name>join_wheel_left</joint_name>
      <joint_name>join_wheel_right</joint_name>
    </plugin>
  </gazebo>
  <gazebo>
    <plugin filename="ignition-gazebo-sensors-system" name="gz::sim::systems::Sensors">
      <render_engine>ogre2</render_engine>
    </plugin>
  </gazebo>
  <gazebo reference="depth_camera">
    <sensor name="depth_camera" type="depth_camera">
      <update_rate>10</update_rate>
      <topic>depth_camera</topic>
      <camera>
        <horizontal_fov>1.05</horizontal_fov>
        <image>
          <width>256</width>
          <height>256</height>
          <format>R_FLOAT32</format>
        </image>
        <clip>
          <near>0.1</near>
          <far>10.0</far>
        </clip>
      </camera>
    </sensor>
  </gazebo>
</robot>
